Workbook

Sheet Yıllık Çalışma Planı
C1: İŞ SAĞLIĞI VE GÜVENLİĞİ YILLIK ÇALIŞMA PLANI – 2026
A2: Firma / İşyeri Adı | C2: VİZYON TESİSAT İNŞAAT HAFRİYAT NAKLİYAT ÇELİK KONSTRÜKSİYON ENERJİ SANAYİ VE TİCARET LİMİTED ŞİRKETİ | AD2: Doküman No | AE2: İSG-PL-01
A3: Adres | C3: ŞAPÇI MAH. ŞAPÇI BURSA MUSTAFAKEMALPAŞ NO:1/133 | AD3: Yayın Tarihi | AE3: 46276
A4: SGK Sicil No | AD4: Revizyon No | AE4: 00
A5: Çalışma Yılı | C5: 2026 | AD5: Revizyon Tarihi
F6: OCAK | H6: ŞUBAT | J6: MART | L6: NİSAN | N6: MAYIS | P6: HAZİRAN | R6: TEMMUZ | T6: AĞUSTOS | V6: EYLÜL | X6: EKİM | Z6: KASIM | AB6: ARALIK | AD6: Hazırlanma Tarihi:11.09.2026
A7: No | B7: Ana Konu | C7: Planlanan Faaliyet | D7: Periyot | E7: Sorumlu | F7: P | G7: G | H7: P | I7: G | J7: P | K7: G | L7: P | M7: G | N7: P | O7: G | P7: P | Q7: G | R7: P | S7: G | T7: P | U7: G | V7: P | W7: G | X7: P | Y7: G | Z7: P | AA7: G | AB7: P | AC7: G | AD7: Mevzuat Dayanağı / Kayıt-Kanıt / Açıklama | AE7: Durum
A8: 1 | B8: PLANLAMA VE DOKÜMANTASYON | C8: Yıllık çalışma planının hazırlanması / gözden geçirilmesi | D8: Yılda 1 | E8: İşveren / İGU / İşyeri Hekimi | AB8: P | AD8: 6331 sayılı İSG Kanunu; İş Sağlığı ve Güvenliği Hizmetleri Yönetmeliği; İş Güvenliği Uzmanları Yönetmeliği; İşyeri Hekimi Yönetmeliği Kayıt/Not: İSG yönetim sistemi | AE8: Planlandı
A9: 2 | B9: PLANLAMA VE DOKÜMANTASYON | C9: Yıllık eğitim planının hazırlanması / gözden geçirilmesi | D9: Yılda 1 | E9: İşveren / İGU / İşyeri Hekimi | AB9: P | AD9: Çalışanların İş Sağlığı ve Güvenliği Eğitimlerinin Usul ve Esasları Hakkında Yönetmelik; İşyeri Hekimi Yönetmeliği Kayıt/Not: Eğitim planlaması | AE9: Planlandı
A10: 3 | B10: PLANLAMA VE DOKÜMANTASYON | C10: Yıllık değerlendirme raporunun hazırlanması | D10: Yılda 1 | E10: İşveren / İGU / İşyeri Hekimi | AB10: P | AD10: İş Sağlığı ve Güvenliği Hizmetleri Yönetmeliği; İşyeri Hekimi Yönetmeliği Kayıt/Not: Yıl sonu değerlendirme | AE10: Planlandı
A11: 4 | B11: RİSK YÖNETİMİ | C11: Risk değerlendirmesinin gözden geçirilmesi; değişiklik, kaza veya ihtiyaç halinde revizyon | D11: Sürekli / Gerektiğinde | E11: İşveren / İGU / İşyeri Hekimi / RD Ekibi | V11: P | X11: P | Z11: P | AB11: P | AD11: 6331 sayılı İSG Kanunu md.10; İş Sağlığı ve Güvenliği Risk Değerlendirmesi Yönetmeliği Kayıt/Not: Risk değerlendirmesi | AE11: Planlandı
A12: 5 | B12: RİSK YÖNETİMİ | C12: Saha gözetimi, tespit ve önerilerin kayıt altına alınması | D12: Aylık / Sürekli | E12: İGU / İşyeri Hekimi / Bölüm Sorumluları | V12: P | X12: P | Z12: P | AB12: P | AD12: 6331 sayılı İSG Kanunu; İş Güvenliği Uzmanlarının Görev, Yetki, Sorumluluk ve Eğitimleri Hakkında Yönetmelik Kayıt/Not: Saha gözetimi | AE12: Planlandı
A13: 6 | B13: RİSK YÖNETİMİ | C13: Tespit edilen uygunsuzluklar için DÖF açılması ve kapanış takibi | D13: Sürekli | E13: İGU / İşveren / Bölüm Sorumluları | V13: P | X13: P | Z13: P | AB13: P | AD13: 6331 sayılı İSG Kanunu; Risk Değerlendirmesi Yönetmeliği Kayıt/Not: DÖF takibi | AE13: Planlandı
A14: 7 | B14: EĞİTİM | C14: Yeni başlayan ve eğitimi yenilenecek çalışanların temel İSG eğitimlerinin planlanması | D14: Gerektiğinde | E14: İGU / İşyeri Hekimi / Yetkili Eğitici | V14: P | X14: P | Z14: P | AB14: P | AD14: İSG eğitimleri | AE14: Planlandı
A15: 8 | B15: EĞİTİM | C15: İşe ve riske özgü toolbox / kısa saha eğitimleri | D15: Aylık | E15: İGU / Bölüm Sorumluları | V15: P | X15: P | Z15: P | AB15: P | AD15: 6331 sayılı İSG Kanunu md.17; Çalışanların İSG Eğitimleri Yönetmeliği Kayıt/Not: Saha eğitimi | AE15: Planlandı
A16: 9 | B16: ACİL DURUM | C16: Acil durum planının gözden geçirilmesi ve gerektiğinde güncellenmesi | D16: Yılda 1 / Gerektiğinde | E16: İşveren / İGU / İşyeri Hekimi | X16: P | AD16: İşyerlerinde Acil Durumlar Hakkında Yönetmelik Kayıt/Not: Acil durum | AE16: Planlandı
A17: 10 | B17: ACİL DURUM | C17: Acil durum ekipleri ve görevlendirmelerin kontrolü / güncellenmesi | D17: Yılda 1 / Değişiklikte | E17: İşveren / İGU / İşyeri Hekimi | X17: P | AD17: İşyerlerinde Acil Durumlar Hakkında Yönetmelik Kayıt/Not: Görevlendirme | AE17: Planlandı
A18: 11 | B18: ACİL DURUM | C18: Yangın, tahliye ve kurtarma tatbikatının planlanması ve uygulanması | D18: Yılda en az 1 | E18: İşveren / İGU / Acil Durum Ekipleri | V18: P | AD18: İşyerlerinde Acil Durumlar Hakkında Yönetmelik Kayıt/Not: Tatbikat | AE18: Planlandı
A19: 12 | B19: ACİL DURUM | C19: Acil çıkış yolları, kapıları, yönlendirme levhaları ve acil aydınlatmanın kontrolü | D19: Aylık | E19: İşveren / İGU / Teknik Birim | V19: P | X19: P | Z19: P | AB19: P | AD19: İşyeri Bina ve Eklentilerinde Alınacak Sağlık ve Güvenlik Önlemlerine İlişkin Yönetmelik; Binaların Yangından Korunması Hakkında Yönetmelik Kayıt/Not: Acil çıkış | AE19: Planlandı
A20: 13 | B20: YANGIN GÜVENLİĞİ | C20: Yangın söndürücüler, hortumlar, hidrant/sprinkler ve yangın ekipmanlarının kontrol takibi | D20: Periyodik / Üretici ve mevzuata göre | E20: İşveren / Teknik Birim / Yetkili Firma | X20: P | AD20: Binaların Yangından Korunması Hakkında Yönetmelik; İşyerlerinde Acil Durumlar Hakkında Yönetmelik Kayıt/Not: Yangın ekipmanı | AE20: Planlandı
A21: 14 | B21: YANGIN GÜVENLİĞİ | C21: Yangın algılama, ihbar, duman/ısı sensörü ve alarm sistemlerinin test/kontrol takibi | D21: Periyodik | E21: İşveren / Teknik Birim / Yetkili Firma | X21: P | AD21: Binaların Yangından Korunması Hakkında Yönetmelik Kayıt/Not: Yangın algılama | AE21: Planlandı
A22: 15 | B22: İŞ EKİPMANLARI | C22: Kaldırma ve iletme ekipmanlarının periyodik kontrol takibi | D22: Mevzuat / ekipmana göre | E22: İşveren / Teknik Birim / Yetkili Kişi | X22: P | AD22: İş Ekipmanlarının Kullanımında Sağlık ve Güvenlik Şartları Yönetmeliği Kayıt/Not: Vinç, forklift, transpalet vb. | AE22: Planlandı
A23: 16 | B23: İŞ EKİPMANLARI | C23: Basınçlı kap ve tesisatların periyodik kontrol takibi | D23: Mevzuat / ekipmana göre | E23: İşveren / Teknik Birim / Yetkili Kişi | X23: P | AD23: İş Ekipmanlarının Kullanımında Sağlık ve Güvenlik Şartları Yönetmeliği Kayıt/Not: Kompresör, kazan, hidrofor vb. | AE23: Planlandı
A24: 17 | B24: ELEKTRİK | C24: Elektrik tesisatı, panolar, prizler, kablolar ve kaçak akım koruma düzenlerinin saha kontrolü | D24: 3 Aylık / Gerektiğinde | E24: İşveren / Teknik Birim / İGU | X24: P | Z24: P | AB24: P | AD24: İş Ekipmanlarının Kullanımında Sağlık ve Güvenlik Şartları Yönetmeliği; Elektrik Tesislerinde Topraklamalar Yönetmeliği Kayıt/Not: Elektrik güvenliği | AE24: Planlandı
A25: 18 | B25: ELEKTRİK | C25: Elektrik tesisatı, topraklama ve yıldırımdan korunma tesisatı periyodik kontrol takibi | D25: Mevzuata göre | E25: İşveren / Yetkili Kişi | Z25: P | AD25: İş Ekipmanlarının Kullanımında Sağlık ve Güvenlik Şartları Yönetmeliği; Elektrik Tesislerinde Topraklamalar Yönetmeliği Kayıt/Not: Periyodik kontrol | AE25: Planlandı
A26: 19 | B26: MAKİNE GÜVENLİĞİ | C26: Makine koruyucuları, acil stoplar, switchler, kullanım talimatları ve güvenli kullanım kontrolleri | D26: Aylık | E26: İGU / Teknik Birim / Bölüm Sorumluları | V26: P | X26: P | Z26: P | AB26: P | AD26: İş Ekipmanlarının Kullanımında Sağlık ve Güvenlik Şartları Yönetmeliği Kayıt/Not: Makine güvenliği | AE26: Planlandı
A27: 20 | B27: KKD | C27: KKD ihtiyaçlarının belirlenmesi, uygun KKD temini ve zimmetle teslimi | D27: Sürekli | E27: İşveren / İGU / Bölüm Sorumluları | V27: P | X27: P | Z27: P | AB27: P | AD27: Kişisel Koruyucu Donanımların İşyerlerinde Kullanılması Hakkında Yönetmelik Kayıt/Not: KKD | AE27: Planlandı
A28: 21 | B28: KKD | C28: KKD kullanımının saha denetimi | D28: Aylık / Sürekli | E28: İGU / Bölüm Sorumluları | V28: P | X28: P | Z28: P | AB28: P | AD28: Kişisel Koruyucu Donanımların İşyerlerinde Kullanılması Hakkında Yönetmelik Kayıt/Not: KKD denetimi | AE28: Planlandı
A29: 22 | B29: İŞYERİ DÜZENİ | C29: Sağlık ve güvenlik işaretleri, korkuluklar, tehlikeli boşluklar, yaya yolları ve genel tertip-düzen kontrolü | D29: Aylık | E29: İGU / Bölüm Sorumluları | V29: P | X29: P | Z29: P | AB29: P | AD29: Sağlık ve Güvenlik İşaretleri Yönetmeliği; İşyeri Bina ve Eklentileri Yönetmeliği Kayıt/Not: İşyeri düzeni | AE29: Planlandı
A30: 23 | B30: KİMYASAL | C30: Kimyasal envanter, etiketler ve Güvenlik Bilgi Formlarının kontrolü | D30: 6 Aylık / Değişiklikte | E30: İGU / İşyeri Hekimi / Bölüm Sorumluları | V30: P | X30: P | Z30: P | AB30: P | AD30: Kimyasal Maddelerle Çalışmalarda Sağlık ve Güvenlik Önlemleri Hakkında Yönetmelik Kayıt/Not: Kimyasal güvenlik | AE30: Planlandı
A31: 24 | B31: PATLAYICI ORTAM | C31: Patlamadan korunma dokümanı ve patlayıcı ortam risklerinin gözden geçirilmesi (uygulanıyorsa) | D31: Değişiklikte / Gerektiğinde | E31: İşveren / İGU / Yetkili Uzman | Z31: P | AD31: Çalışanların Patlayıcı Ortamların Tehlikelerinden Korunması Hakkında Yönetmelik Kayıt/Not: ATEX | AE31: Planlandı
A32: 25 | B32: ORTAM ÖLÇÜMLERİ | C32: Gürültü, toz, titreşim, aydınlatma, termal konfor, gaz/VOC vb. ölçüm ihtiyacının değerlendirilmesi ve ölçümlerin planlanması | D32: Risk değerlendirmesine göre | E32: İşveren / İGU / İşyeri Hekimi | AB32: P | AD32: İş Hijyeni Ölçüm, Test ve Analizleri Hakkında Yönetmelik; ilgili maruziyet yönetmelikleri Kayıt/Not: İş hijyeni | AE32: Planlandı
A33: 26 | B33: SAĞLIK GÖZETİMİ | C33: İşe giriş sağlık muayeneleri | D33: İşe girişte | E33: İşveren / İşyeri Hekimi | V33: P | X33: P | Z33: P | AB33: P | AD33: Sağlık gözetimi | AE33: Planlandı
A34: 27 | B34: SAĞLIK GÖZETİMİ | C34: Periyodik sağlık muayeneleri ve işe/risklere özgü tetkiklerin planlanması | D34: Risk ve mevzuata göre | E34: İşyeri Hekimi / İşveren | V34: P | X34: P | Z34: P | AB34: P | AD34: 6331 sayılı İSG Kanunu md.15; İşyeri Hekimi ve Diğer Sağlık Personeli Yönetmeliği Kayıt/Not: Sağlık gözetimi | AE34: Planlandı
A35: 28 | B35: SAĞLIK GÖZETİMİ | C35: İlk yardım dolapları ve sağlık ekipmanlarının kontrolü | D35: Aylık / Periyodik | E35: İşyeri Hekimi / Görevlendirilen Personel | V35: P | X35: P | Z35: P | AB35: P | AD35: İlk yardım | AE35: Planlandı
A36: 29 | B36: HİJYEN | C36: İçme-kullanma suyu, yemekhane, tuvalet, soyunma alanları ve genel hijyen kontrolleri | D36: Periyodik | E36: İşyeri Hekimi / İşveren / İlgili Birim | Z36: P | AD36: İşyeri Bina ve Eklentileri Yönetmeliği; İşyeri Hekimi ve Diğer Sağlık Personeli Yönetmeliği Kayıt/Not: Hijyen | AE36: Planlandı
A37: 30 | B37: KAZA / RAMAK KALA | C37: İş kazaları, ramak kala olayları ve ilk yardım vakalarının kayıt, inceleme ve kök neden takibi | D37: Olay oldukça | E37: İşveren / İGU / İşyeri Hekimi | V37: P | X37: P | Z37: P | AB37: P | AD37: İlkyardım Yönetmeliği; İşyeri Hekimi ve Diğer Sağlık Personeli Yönetmeliği Kayıt/Not: Olay yönetimi | AE37: Planlandı
A38: 31 | B38: ÇALIŞAN KATILIMI | C38: Çalışan temsilcisi ve destek elemanlarının görevlendirme/atamalarının kontrolü | D38: Yılda 1 / Değişiklikte | E38: İşveren / İGU | V38: P | AD38: 6331 sayılı İSG Kanunu md.20 Kayıt/Not: Görevlendirme | AE38: Planlandı
A39: 32 | B39: İSG KURULU | C39: İSG Kurulu üyeliklerinin ve toplantı planının kontrolü; toplantıların mevzuat periyodunda yapılması (uygulanıyorsa) | D39: Mevzuat periyodunda | E39: İşveren / İGU / İşyeri Hekimi / Kurul | V39: P | AD39: İSG Kurulu | AE39: Planlandı
A40: 33 | B40: ALT İŞVEREN | C40: Alt işveren / taşeron çalışmalarının İSG evrak, iş izinleri ve saha uygulamaları yönünden kontrolü | D40: Her çalışma öncesi / Sürekli | E40: İşveren / İGU / Saha Sorumluları | V40: P | X40: P | Z40: P | AB40: P | AD40: 6331 sayılı İSG Kanunu; İş Sağlığı ve Güvenliği Hizmetleri Yönetmeliği Kayıt/Not: İş izinleri | AE40: Planlandı
...

Sheet Aylık Özet
A1: 2027 İSG YILLIK ÇALIŞMA PLANI – AYLIK ÖZET
A3: Ana Konu | B3: OCAK | C3: ŞUBAT | D3: MART | E3: NİSAN | F3: MAYIS | G3: HAZİRAN | H3: TEMMUZ | I3: AĞUSTOS | J3: EYLÜL | K3: EKİM | L3: KASIM | M3: ARALIK | N3: Toplam
A4: PLANLAMA VE DOKÜMANTASYON | B4: =COUNTIFS('Yıllık Çalışma Planı'!$B$8:$B$45,$A4,'Yıllık Çalışma Planı'!$F$8:$F$45,"P") -> 0 | C4: =COUNTIFS('Yıllık Çalışma Planı'!$B$8:$B$45,$A4,'Yıllık Çalışma Planı'!$H$8:$H$45,"P") -> 0 | D4: =COUNTIFS('Yıllık Çalışma Planı'!$B$8:$B$45,$A4,'Yıllık Çalışma Planı'!$J$8:$J$45,"P") -> 0 | E4: =COUNTIFS('Yıllık Çalışma Planı'!$B$8:$B$45,$A4,'Yıllık Çalışma Planı'!$L$8:$L$45,"P") -> 0 | F4: =COUNTIFS('Yıllık Çalışma Planı'!$B$8:$B$45,$A4,'Yıllık Çalışma Planı'!$N$8:$N$45,"P") -> 0 | G4: =COUNTIFS('Yıllık Çalışma Planı'!$B$8:$B$45,$A4,'Yıllık Çalışma Planı'!$P$8:$P$45,"P") -> 0 | H4: =COUNTIFS('Yıllık Çalışma Planı'!$B$8:$B$45,$A4,'Yıllık Çalışma Planı'!$R$8:$R$45,"P") -> 0 | I4: =COUNTIFS('Yıllık Çalışma Planı'!$B$8:$B$45,$A4,'Yıllık Çalışma Planı'!$T$8:$T$43,"P") -> #VALUE! | J4: =COUNTIFS('Yıllık Çalışma Planı'!$B$8:$B$45,$A4,'Yıllık Çalışma Planı'!$V$8:$V$43,"P") -> #VALUE! | K4: =COUNTIFS('Yıllık Çalışma Planı'!$B$8:$B$45,$A4,'Yıllık Çalışma Planı'!$X$8:$X$43,"P") -> #VALUE! | L4: =COUNTIFS('Yıllık Çalışma Planı'!$B$8:$B$45,$A4,'Yıllık Çalışma Planı'!$Z$8:$Z$43,"P") -> #VALUE! | M4: =COUNTIFS('Yıllık Çalışma Planı'!$B$8:$B$45,$A4,'Yıllık Çalışma Planı'!$AB$8:$AB$43,"P") -> #VALUE! | N4: =SUM(B4:M4) -> #VALUE!
A5: RİSK YÖNETİMİ | B5: =COUNTIFS('Yıllık Çalışma Planı'!$B$8:$B$45,$A5,'Yıllık Çalışma Planı'!$F$8:$F$45,"P") -> 0 | C5: =COUNTIFS('Yıllık Çalışma Planı'!$B$8:$B$45,$A5,'Yıllık Çalışma Planı'!$H$8:$H$45,"P") -> 0 | D5: =COUNTIFS('Yıllık Çalışma Planı'!$B$8:$B$45,$A5,'Yıllık Çalışma Planı'!$J$8:$J$45,"P") -> 0 | E5: =COUNTIFS('Yıllık Çalışma Planı'!$B$8:$B$45,$A5,'Yıllık Çalışma Planı'!$L$8:$L$45,"P") -> 0 | F5: =COUNTIFS('Yıllık Çalışma Planı'!$B$8:$B$45,$A5,'Yıllık Çalışma Planı'!$N$8:$N$45,"P") -> 0 | G5: =COUNTIFS('Yıllık Çalışma Planı'!$B$8:$B$45,$A5,'Yıllık Çalışma Planı'!$P$8:$P$45,"P") -> 0 | H5: =COUNTIFS('Yıllık Çalışma Planı'!$B$8:$B$45,$A5,'Yıllık Çalışma Planı'!$R$8:$R$45,"P") -> 0 | I5: =COUNTIFS('Yıllık Çalışma Planı'!$B$8:$B$45,$A5,'Yıllık Çalışma Planı'!$T$8:$T$43,"P") -> #VALUE! | J5: =COUNTIFS('Yıllık Çalışma Planı'!$B$8:$B$45,$A5,'Yıllık Çalışma Planı'!$V$8:$V$43,"P") -> #VALUE! | K5: =COUNTIFS('Yıllık Çalışma Planı'!$B$8:$B$45,$A5,'Yıllık Çalışma Planı'!$X$8:$X$43,"P") -> #VALUE! | L5: =COUNTIFS('Yıllık Çalışma Planı'!$B$8:$B$45,$A5,'Yıllık Çalışma Planı'!$Z$8:$Z$43,"P") -> #VALUE! | M5: =COUNTIFS('Yıllık Çalışma Planı'!$B$8:$B$45,$A5,'Yıllık Çalışma Planı'!$AB$8:$AB$43,"P") -> #VALUE! | N5: =SUM(B5:M5) -> #VALUE!
A6: EĞİTİM | B6: =COUNTIFS('Yıllık Çalışma Planı'!$B$8:$B$45,$A6,'Yıllık Çalışma Planı'!$F$8:$F$45,"P") -> 0 | C6: =COUNTIFS('Yıllık Çalışma Planı'!$B$8:$B$45,$A6,'Yıllık Çalışma Planı'!$H$8:$H$45,"P") -> 0 | D6: =COUNTIFS('Yıllık Çalışma Planı'!$B$8:$B$45,$A6,'Yıllık Çalışma Planı'!$J$8:$J$45,"P") -> 0 | E6: =COUNTIFS('Yıllık Çalışma Planı'!$B$8:$B$45,$A6,'Yıllık Çalışma Planı'!$L$8:$L$45,"P") -> 0 | F6: =COUNTIFS('Yıllık Çalışma Planı'!$B$8:$B$45,$A6,'Yıllık Çalışma Planı'!$N$8:$N$45,"P") -> 0 | G6: =COUNTIFS('Yıllık Çalışma Planı'!$B$8:$B$45,$A6,'Yıllık Çalışma Planı'!$P$8:$P$45,"P") -> 0 | H6: =COUNTIFS('Yıllık Çalışma Planı'!$B$8:$B$45,$A6,'Yıllık Çalışma Planı'!$R$8:$R$45,"P") -> 0 | I6: =COUNTIFS('Yıllık Çalışma Planı'!$B$8:$B$45,$A6,'Yıllık Çalışma Planı'!$T$8:$T$43,"P") -> #VALUE! | J6: =COUNTIFS('Yıllık Çalışma Planı'!$B$8:$B$45,$A6,'Yıllık Çalışma Planı'!$V$8:$V$43,"P") -> #VALUE! | K6: =COUNTIFS('Yıllık Çalışma Planı'!$B$8:$B$45,$A6,'Yıllık Çalışma Planı'!$X$8:$X$43,"P") -> #VALUE! | L6: =COUNTIFS('Yıllık Çalışma Planı'!$B$8:$B$45,$A6,'Yıllık Çalışma Planı'!$Z$8:$Z$43,"P") -> #VALUE! | M6: =COUNTIFS('Yıllık Çalışma Planı'!$B$8:$B$45,$A6,'Yıllık Çalışma Planı'!$AB$8:$AB$43,"P") -> #VALUE! | N6: =SUM(B6:M6) -> #VALUE!
A7: ACİL DURUM | B7: =COUNTIFS('Yıllık Çalışma Planı'!$B$8:$B$45,$A7,'Yıllık Çalışma Planı'!$F$8:$F$45,"P") -> 0 | C7: =COUNTIFS('Yıllık Çalışma Planı'!$B$8:$B$45,$A7,'Yıllık Çalışma Planı'!$H$8:$H$45,"P") -> 0 | D7: =COUNTIFS('Yıllık Çalışma Planı'!$B$8:$B$45,$A7,'Yıllık Çalışma Planı'!$J$8:$J$45,"P") -> 0 | E7: =COUNTIFS('Yıllık Çalışma Planı'!$B$8:$B$45,$A7,'Yıllık Çalışma Planı'!$L$8:$L$45,"P") -> 0 | F7: =COUNTIFS('Yıllık Çalışma Planı'!$B$8:$B$45,$A7,'Yıllık Çalışma Planı'!$N$8:$N$45,"P") -> 0 | G7: =COUNTIFS('Yıllık Çalışma Planı'!$B$8:$B$45,$A7,'Yıllık Çalışma Planı'!$P$8:$P$45,"P") -> 0 | H7: =COUNTIFS('Yıllık Çalışma Planı'!$B$8:$B$45,$A7,'Yıllık Çalışma Planı'!$R$8:$R$45,"P") -> 0 | I7: =COUNTIFS('Yıllık Çalışma Planı'!$B$8:$B$45,$A7,'Yıllık Çalışma Planı'!$T$8:$T$43,"P") -> #VALUE! | J7: =COUNTIFS('Yıllık Çalışma Planı'!$B$8:$B$45,$A7,'Yıllık Çalışma Planı'!$V$8:$V$43,"P") -> #VALUE! | K7: =COUNTIFS('Yıllık Çalışma Planı'!$B$8:$B$45,$A7,'Yıllık Çalışma Planı'!$X$8:$X$43,"P") -> #VALUE! | L7: =COUNTIFS('Yıllık Çalışma Planı'!$B$8:$B$45,$A7,'Yıllık Çalışma Planı'!$Z$8:$Z$43,"P") -> #VALUE! | M7: =COUNTIFS('Yıllık Çalışma Planı'!$B$8:$B$45,$A7,'Yıllık Çalışma Planı'!$AB$8:$AB$43,"P") -> #VALUE! | N7: =SUM(B7:M7) -> #VALUE!
A8: YANGIN GÜVENLİĞİ | B8: =COUNTIFS('Yıllık Çalışma Planı'!$B$8:$B$45,$A8,'Yıllık Çalışma Planı'!$F$8:$F$45,"P") -> 0 | C8: =COUNTIFS('Yıllık Çalışma Planı'!$B$8:$B$45,$A8,'Yıllık Çalışma Planı'!$H$8:$H$45,"P") -> 0 | D8: =COUNTIFS('Yıllık Çalışma Planı'!$B$8:$B$45,$A8,'Yıllık Çalışma Planı'!$J$8:$J$45,"P") -> 0 | E8: =COUNTIFS('Yıllık Çalışma Planı'!$B$8:$B$45,$A8,'Yıllık Çalışma Planı'!$L$8:$L$45,"P") -> 0 | F8: =COUNTIFS('Yıllık Çalışma Planı'!$B$8:$B$45,$A8,'Yıllık Çalışma Planı'!$N$8:$N$45,"P") -> 0 | G8: =COUNTIFS('Yıllık Çalışma Planı'!$B$8:$B$45,$A8,'Yıllık Çalışma Planı'!$P$8:$P$45,"P") -> 0 | H8: =COUNTIFS('Yıllık Çalışma Planı'!$B$8:$B$45,$A8,'Yıllık Çalışma Planı'!$R$8:$R$45,"P") -> 0 | I8: =COUNTIFS('Yıllık Çalışma Planı'!$B$8:$B$45,$A8,'Yıllık Çalışma Planı'!$T$8:$T$43,"P") -> #VALUE! | J8: =COUNTIFS('Yıllık Çalışma Planı'!$B$8:$B$45,$A8,'Yıllık Çalışma Planı'!$V$8:$V$43,"P") -> #VALUE! | K8: =COUNTIFS('Yıllık Çalışma Planı'!$B$8:$B$45,$A8,'Yıllık Çalışma Planı'!$X$8:$X$43,"P") -> #VALUE! | L8: =COUNTIFS('Yıllık Çalışma Planı'!$B$8:$B$45,$A8,'Yıllık Çalışma Planı'!$Z$8:$Z$43,"P") -> #VALUE! | M8: =COUNTIFS('Yıllık Çalışma Planı'!$B$8:$B$45,$A8,'Yıllık Çalışma Planı'!$AB$8:$AB$43,"P") -> #VALUE! | N8: =SUM(B8:M8) -> #VALUE!
A9: İŞ EKİPMANLARI | B9: =COUNTIFS('Yıllık Çalışma Planı'!$B$8:$B$45,$A9,'Yıllık Çalışma Planı'!$F$8:$F$45,"P") -> 0 | C9: =COUNTIFS('Yıllık Çalışma Planı'!$B$8:$B$45,$A9,'Yıllık Çalışma Planı'!$H$8:$H$45,"P") -> 0 | D9: =COUNTIFS('Yıllık Çalışma Planı'!$B$8:$B$45,$A9,'Yıllık Çalışma Planı'!$J$8:$J$45,"P") -> 0 | E9: =COUNTIFS('Yıllık Çalışma Planı'!$B$8:$B$45,$A9,'Yıllık Çalışma Planı'!$L$8:$L$45,"P") -> 0 | F9: =COUNTIFS('Yıllık Çalışma Planı'!$B$8:$B$45,$A9,'Yıllık Çalışma Planı'!$N$8:$N$45,"P") -> 0 | G9: =COUNTIFS('Yıllık Çalışma Planı'!$B$8:$B$45,$A9,'Yıllık Çalışma Planı'!$P$8:$P$45,"P") -> 0 | H9: =COUNTIFS('Yıllık Çalışma Planı'!$B$8:$B$45,$A9,'Yıllık Çalışma Planı'!$R$8:$R$45,"P") -> 0 | I9: =COUNTIFS('Yıllık Çalışma Planı'!$B$8:$B$45,$A9,'Yıllık Çalışma Planı'!$T$8:$T$43,"P") -> #VALUE! | J9: =COUNTIFS('Yıllık Çalışma Planı'!$B$8:$B$45,$A9,'Yıllık Çalışma Planı'!$V$8:$V$43,"P") -> #VALUE! | K9: =COUNTIFS('Yıllık Çalışma Planı'!$B$8:$B$45,$A9,'Yıllık Çalışma Planı'!$X$8:$X$43,"P") -> #VALUE! | L9: =COUNTIFS('Yıllık Çalışma Planı'!$B$8:$B$45,$A9,'Yıllık Çalışma Planı'!$Z$8:$Z$43,"P") -> #VALUE! | M9: =COUNTIFS('Yıllık Çalışma Planı'!$B$8:$B$45,$A9,'Yıllık Çalışma Planı'!$AB$8:$AB$43,"P") -> #VALUE! | N9: =SUM(B9:M9) -> #VALUE!
A10: ELEKTRİK | B10: =COUNTIFS('Yıllık Çalışma Planı'!$B$8:$B$45,$A10,'Yıllık Çalışma Planı'!$F$8:$F$45,"P") -> 0 | C10: =COUNTIFS('Yıllık Çalışma Planı'!$B$8:$B$45,$A10,'Yıllık Çalışma Planı'!$H$8:$H$45,"P") -> 0 | D10: =COUNTIFS('Yıllık Çalışma Planı'!$B$8:$B$45,$A10,'Yıllık Çalışma Planı'!$J$8:$J$45,"P") -> 0 | E10: =COUNTIFS('Yıllık Çalışma Planı'!$B$8:$B$45,$A10,'Yıllık Çalışma Planı'!$L$8:$L$45,"P") -> 0 | F10: =COUNTIFS('Yıllık Çalışma Planı'!$B$8:$B$45,$A10,'Yıllık Çalışma Planı'!$N$8:$N$45,"P") -> 0 | G10: =COUNTIFS('Yıllık Çalışma Planı'!$B$8:$B$45,$A10,'Yıllık Çalışma Planı'!$P$8:$P$45,"P") -> 0 | H10: =COUNTIFS('Yıllık Çalışma Planı'!$B$8:$B$45,$A10,'Yıllık Çalışma Planı'!$R$8:$R$45,"P") -> 0 | I10: =COUNTIFS('Yıllık Çalışma Planı'!$B$8:$B$45,$A10,'Yıllık Çalışma Planı'!$T$8:$T$43,"P") -> #VALUE! | J10: =COUNTIFS('Yıllık Çalışma Planı'!$B$8:$B$45,$A10,'Yıllık Çalışma Planı'!$V$8:$V$43,"P") -> #VALUE! | K10: =COUNTIFS('Yıllık Çalışma Planı'!$B$8:$B$45,$A10,'Yıllık Çalışma Planı'!$X$8:$X$43,"P") -> #VALUE! | L10: =COUNTIFS('Yıllık Çalışma Planı'!$B$8:$B$45,$A10,'Yıllık Çalışma Planı'!$Z$8:$Z$43,"P") -> #VALUE! | M10: =COUNTIFS('Yıllık Çalışma Planı'!$B$8:$B$45,$A10,'Yıllık Çalışma Planı'!$AB$8:$AB$43,"P") -> #VALUE! | N10: =SUM(B10:M10) -> #VALUE!
A11: MAKİNE GÜVENLİĞİ | B11: =COUNTIFS('Yıllık Çalışma Planı'!$B$8:$B$45,$A11,'Yıllık Çalışma Planı'!$F$8:$F$45,"P") -> 0 | C11: =COUNTIFS('Yıllık Çalışma Planı'!$B$8:$B$45,$A11,'Yıllık Çalışma Planı'!$H$8:$H$45,"P") -> 0 | D11: =COUNTIFS('Yıllık Çalışma Planı'!$B$8:$B$45,$A11,'Yıllık Çalışma Planı'!$J$8:$J$45,"P") -> 0 | E11: =COUNTIFS('Yıllık Çalışma Planı'!$B$8:$B$45,$A11,'Yıllık Çalışma Planı'!$L$8:$L$45,"P") -> 0 | F11: =COUNTIFS('Yıllık Çalışma Planı'!$B$8:$B$45,$A11,'Yıllık Çalışma Planı'!$N$8:$N$45,"P") -> 0 | G11: =COUNTIFS('Yıllık Çalışma Planı'!$B$8:$B$45,$A11,'Yıllık Çalışma Planı'!$P$8:$P$45,"P") -> 0 | H11: =COUNTIFS('Yıllık Çalışma Planı'!$B$8:$B$45,$A11,'Yıllık Çalışma Planı'!$R$8:$R$45,"P") -> 0 | I11: =COUNTIFS('Yıllık Çalışma Planı'!$B$8:$B$45,$A11,'Yıllık Çalışma Planı'!$T$8:$T$43,"P") -> #VALUE! | J11: =COUNTIFS('Yıllık Çalışma Planı'!$B$8:$B$45,$A11,'Yıllık Çalışma Planı'!$V$8:$V$43,"P") -> #VALUE! | K11: =COUNTIFS('Yıllık Çalışma Planı'!$B$8:$B$45,$A11,'Yıllık Çalışma Planı'!$X$8:$X$43,"P") -> #VALUE! | L11: =COUNTIFS('Yıllık Çalışma Planı'!$B$8:$B$45,$A11,'Yıllık Çalışma Planı'!$Z$8:$Z$43,"P") -> #VALUE! | M11: =COUNTIFS('Yıllık Çalışma Planı'!$B$8:$B$45,$A11,'Yıllık Çalışma Planı'!$AB$8:$AB$43,"P") -> #VALUE! | N11: =SUM(B11:M11) -> #VALUE!
A12: KKD | B12: =COUNTIFS('Yıllık Çalışma Planı'!$B$8:$B$45,$A12,'Yıllık Çalışma Planı'!$F$8:$F$45,"P") -> 0 | C12: =COUNTIFS('Yıllık Çalışma Planı'!$B$8:$B$45,$A12,'Yıllık Çalışma Planı'!$H$8:$H$45,"P") -> 0 | D12: =COUNTIFS('Yıllık Çalışma Planı'!$B$8:$B$45,$A12,'Yıllık Çalışma Planı'!$J$8:$J$45,"P") -> 0 | E12: =COUNTIFS('Yıllık Çalışma Planı'!$B$8:$B$45,$A12,'Yıllık Çalışma Planı'!$L$8:$L$45,"P") -> 0 | F12: =COUNTIFS('Yıllık Çalışma Planı'!$B$8:$B$45,$A12,'Yıllık Çalışma Planı'!$N$8:$N$45,"P") -> 0 | G12: =COUNTIFS('Yıllık Çalışma Planı'!$B$8:$B$45,$A12,'Yıllık Çalışma Planı'!$P$8:$P$45,"P") -> 0 | H12: =COUNTIFS('Yıllık Çalışma Planı'!$B$8:$B$45,$A12,'Yıllık Çalışma Planı'!$R$8:$R$45,"P") -> 0 | I12: =COUNTIFS('Yıllık Çalışma Planı'!$B$8:$B$45,$A12,'Yıllık Çalışma Planı'!$T$8:$T$43,"P") -> #VALUE! | J12: =COUNTIFS('Yıllık Çalışma Planı'!$B$8:$B$45,$A12,'Yıllık Çalışma Planı'!$V$8:$V$43,"P") -> #VALUE! | K12: =COUNTIFS('Yıllık Çalışma Planı'!$B$8:$B$45,$A12,'Yıllık Çalışma Planı'!$X$8:$X$43,"P") -> #VALUE! | L12: =COUNTIFS('Yıllık Çalışma Planı'!$B$8:$B$45,$A12,'Yıllık Çalışma Planı'!$Z$8:$Z$43,"P") -> #VALUE! | M12: =COUNTIFS('Yıllık Çalışma Planı'!$B$8:$B$45,$A12,'Yıllık Çalışma Planı'!$AB$8:$AB$43,"P") -> #VALUE! | N12: =SUM(B12:M12) -> #VALUE!
A13: İŞYERİ DÜZENİ | B13: =COUNTIFS('Yıllık Çalışma Planı'!$B$8:$B$45,$A13,'Yıllık Çalışma Planı'!$F$8:$F$45,"P") -> 0 | C13: =COUNTIFS('Yıllık Çalışma Planı'!$B$8:$B$45,$A13,'Yıllık Çalışma Planı'!$H$8:$H$45,"P") -> 0 | D13: =COUNTIFS('Yıllık Çalışma Planı'!$B$8:$B$45,$A13,'Yıllık Çalışma Planı'!$J$8:$J$45,"P") -> 0 | E13: =COUNTIFS('Yıllık Çalışma Planı'!$B$8:$B$45,$A13,'Yıllık Çalışma Planı'!$L$8:$L$45,"P") -> 0 | F13: =COUNTIFS('Yıllık Çalışma Planı'!$B$8:$B$45,$A13,'Yıllık Çalışma Planı'!$N$8:$N$45,"P") -> 0 | G13: =COUNTIFS('Yıllık Çalışma Planı'!$B$8:$B$45,$A13,'Yıllık Çalışma Planı'!$P$8:$P$45,"P") -> 0 | H13: =COUNTIFS('Yıllık Çalışma Planı'!$B$8:$B$45,$A13,'Yıllık Çalışma Planı'!$R$8:$R$45,"P") -> 0 | I13: =COUNTIFS('Yıllık Çalışma Planı'!$B$8:$B$45,$A13,'Yıllık Çalışma Planı'!$T$8:$T$43,"P") -> #VALUE! | J13: =COUNTIFS('Yıllık Çalışma Planı'!$B$8:$B$45,$A13,'Yıllık Çalışma Planı'!$V$8:$V$43,"P") -> #VALUE! | K13: =COUNTIFS('Yıllık Çalışma Planı'!$B$8:$B$45,$A13,'Yıllık Çalışma Planı'!$X$8:$X$43,"P") -> #VALUE! | L13: =COUNTIFS('Yıllık Çalışma Planı'!$B$8:$B$45,$A13,'Yıllık Çalışma Planı'!$Z$8:$Z$43,"P") -> #VALUE! | M13: =COUNTIFS('Yıllık Çalışma Planı'!$B$8:$B$45,$A13,'Yıllık Çalışma Planı'!$AB$8:$AB$43,"P") -> #VALUE! | N13: =SUM(B13:M13) -> #VALUE!
A14: KİMYASAL | B14: =COUNTIFS('Yıllık Çalışma Planı'!$B$8:$B$45,$A14,'Yıllık Çalışma Planı'!$F$8:$F$45,"P") -> 0 | C14: =COUNTIFS('Yıllık Çalışma Planı'!$B$8:$B$45,$A14,'Yıllık Çalışma Planı'!$H$8:$H$45,"P") -> 0 | D14: =COUNTIFS('Yıllık Çalışma Planı'!$B$8:$B$45,$A14,'Yıllık Çalışma Planı'!$J$8:$J$45,"P") -> 0 | E14: =COUNTIFS('Yıllık Çalışma Planı'!$B$8:$B$45,$A14,'Yıllık Çalışma Planı'!$L$8:$L$45,"P") -> 0 | F14: =COUNTIFS('Yıllık Çalışma Planı'!$B$8:$B$45,$A14,'Yıllık Çalışma Planı'!$N$8:$N$45,"P") -> 0 | G14: =COUNTIFS('Yıllık Çalışma Planı'!$B$8:$B$45,$A14,'Yıllık Çalışma Planı'!$P$8:$P$45,"P") -> 0 | H14: =COUNTIFS('Yıllık Çalışma Planı'!$B$8:$B$45,$A14,'Yıllık Çalışma Planı'!$R$8:$R$45,"P") -> 0 | I14: =COUNTIFS('Yıllık Çalışma Planı'!$B$8:$B$45,$A14,'Yıllık Çalışma Planı'!$T$8:$T$43,"P") -> #VALUE! | J14: =COUNTIFS('Yıllık Çalışma Planı'!$B$8:$B$45,$A14,'Yıllık Çalışma Planı'!$V$8:$V$43,"P") -> #VALUE! | K14: =COUNTIFS('Yıllık Çalışma Planı'!$B$8:$B$45,$A14,'Yıllık Çalışma Planı'!$X$8:$X$43,"P") -> #VALUE! | L14: =COUNTIFS('Yıllık Çalışma Planı'!$B$8:$B$45,$A14,'Yıllık Çalışma Planı'!$Z$8:$Z$43,"P") -> #VALUE! | M14: =COUNTIFS('Yıllık Çalışma Planı'!$B$8:$B$45,$A14,'Yıllık Çalışma Planı'!$AB$8:$AB$43,"P") -> #VALUE! | N14: =SUM(B14:M14) -> #VALUE!
A15: PATLAYICI ORTAM | B15: =COUNTIFS('Yıllık Çalışma Planı'!$B$8:$B$45,$A15,'Yıllık Çalışma Planı'!$F$8:$F$45,"P") -> 0 | C15: =COUNTIFS('Yıllık Çalışma Planı'!$B$8:$B$45,$A15,'Yıllık Çalışma Planı'!$H$8:$H$45,"P") -> 0 | D15: =COUNTIFS('Yıllık Çalışma Planı'!$B$8:$B$45,$A15,'Yıllık Çalışma Planı'!$J$8:$J$45,"P") -> 0 | E15: =COUNTIFS('Yıllık Çalışma Planı'!$B$8:$B$45,$A15,'Yıllık Çalışma Planı'!$L$8:$L$45,"P") -> 0 | F15: =COUNTIFS('Yıllık Çalışma Planı'!$B$8:$B$45,$A15,'Yıllık Çalışma Planı'!$N$8:$N$45,"P") -> 0 | G15: =COUNTIFS('Yıllık Çalışma Planı'!$B$8:$B$45,$A15,'Yıllık Çalışma Planı'!$P$8:$P$45,"P") -> 0 | H15: =COUNTIFS('Yıllık Çalışma Planı'!$B$8:$B$45,$A15,'Yıllık Çalışma Planı'!$R$8:$R$45,"P") -> 0 | I15: =COUNTIFS('Yıllık Çalışma Planı'!$B$8:$B$45,$A15,'Yıllık Çalışma Planı'!$T$8:$T$43,"P") -> #VALUE! | J15: =COUNTIFS('Yıllık Çalışma Planı'!$B$8:$B$45,$A15,'Yıllık Çalışma Planı'!$V$8:$V$43,"P") -> #VALUE! | K15: =COUNTIFS('Yıllık Çalışma Planı'!$B$8:$B$45,$A15,'Yıllık Çalışma Planı'!$X$8:$X$43,"P") -> #VALUE! | L15: =COUNTIFS('Yıllık Çalışma Planı'!$B$8:$B$45,$A15,'Yıllık Çalışma Planı'!$Z$8:$Z$43,"P") -> #VALUE! | M15: =COUNTIFS('Yıllık Çalışma Planı'!$B$8:$B$45,$A15,'Yıllık Çalışma Planı'!$AB$8:$AB$43,"P") -> #VALUE! | N15: =SUM(B15:M15) -> #VALUE!
... A25: ERGONOMİ | B25: =COUNTIFS('Yıllık Çalışma Planı'!$B$8:$B$45,$A25,'Yıllık Çalışma Planı'!$F$8:$F$45,"P") -> 0 | C25: =COUNTIFS('Yıllık Çalışma Planı'!$B$8:$B$45,$A25,'Yıllık Çalışma Planı'!$H$8:$H$45,"P") -> 0 | D25: =COUNTIFS('Yıllık Çalışma Planı'!$B$8:$B$45,$A25,'Yıllık Çalışma Planı'!$J$8:$J$45,"P") -> 0 | E25: =COUNTIFS('Yıllık Çalışma Planı'!$B$8:$B$45,$A25,'Yıllık Çalışma Planı'!$L$8:$L$45,"P") -> 0 | F25: =COUNTIFS('Yıllık Çalışma Planı'!$B$8:$B$45,$A25,'Yıllık Çalışma Planı'!$N$8:$N$45,"P") -> 0 | G25: =COUNTIFS('Yıllık Çalışma Planı'!$B$8:$B$45,$A25,'Yıllık Çalışma Planı'!$P$8:$P$45,"P") -> 0 | H25: =COUNTIFS('Yıllık Çalışma Planı'!$B$8:$B$45,$A25,'Yıllık Çalışma Planı'!$R$8:$R$45,"P") -> 0 | I25: =COUNTIFS('Yıllık Çalışma Planı'!$B$8:$B$45,$A25,'Yıllık Çalışma Planı'!$T$8:$T$43,"P") -> #VALUE! | J25: =COUNTIFS('Yıllık Çalışma Planı'!$B$8:$B$45,$A25,'Yıllık Çalışma Planı'!$V$8:$V$43,"P") -> #VALUE! | K25: =COUNTIFS('Yıllık Çalışma Planı'!$B$8:$B$45,$A25,'Yıllık Çalışma Planı'!$X$8:$X$43,"P") -> #VALUE! | L25: =COUNTIFS('Yıllık Çalışma Planı'!$B$8:$B$45,$A25,'Yıllık Çalışma Planı'!$Z$8:$Z$43,"P") -> #VALUE! | M25: =COUNTIFS('Yıllık Çalışma Planı'!$B$8:$B$45,$A25,'Yıllık Çalışma Planı'!$AB$8:$AB$43,"P") -> #VALUE! | N25: =SUM(B25:M25) -> #VALUE!
A26: GENEL TOPLAM | B26: =SUM(B4:B25) -> 0 | C26: =SUM(C4:C25) -> 0 | D26: =SUM(D4:D25) -> 0 | E26: =SUM(E4:E25) -> 0 | F26: =SUM(F4:F25) -> 0 | G26: =SUM(G4:G25) -> 0 | H26: =SUM(H4:H25) -> 0 | I26: =SUM(I4:I25) -> #VALUE! | ... N26: =SUM(N4:N25) -> #VALUE!

Sheet Listeler
A1: Kullanım Notu | B1: Açıklama
A2: P | B2: Planlanan ay
A3: Durum | B3: Planlandı / Devam Ediyor / Tamamlandı / Ertelendi / İptal
A4: Aylık seçim | B4: Ana plandaki G:R sütunlarında P işaretlerini istediğiniz aylara taşıyabilir, silebilir veya ekleyebilirsiniz.
A5: Periyot | B5: İşyerinin tehlike sınıfı, ekipman üretici şartları, risk değerlendirmesi ve güncel mevzuata göre teyit edilmelidir.
A6: Kaynak 1 | B6: YILLIK ÇALIŞMA PLANI.xlsx
A7: Kaynak 2 | B7: 2025 ÇALIŞMA PLANI reform.xlsx
A8: Kaynak 3 | B8: Yıllık Çalışma Planı.xlsx ve yıllık çalışma planı.pdf
A10: Baskı Düzeni | B10: Yıllık Çalışma Planı sayfasında 1:7 satırlar ve A:G sütunları her basılı sayfada tekrar eder. Her basılı sayfanın alt bilgisinde İşveren/İşveren Vekili, İş Güvenliği Uzmanı ve İşyeri Hekimi imza alanları bulunur.
A11: Mevzuat | B11: Faaliyetlerin mevzuat dayanakları planın S sütununa işlendi. Periyotlar işyerine özgü risk, ekipman, üretici şartları ve güncel mevzuata göre ayrıca teyit edilmelidir.
A12: P / G Takibi | B12: Her ay iki alt sütuna ayrılmıştır: P = Planlanan, G = Gerçekleşen. Planlanan aylar P ile işaretlidir. Faaliyet tamamlandığında ilgili ayın G hücresinden G seçilir.
